Workbook

Sheet Panduan
A1: PANDUAN
A3: 1 | B3: Dapatkan jawaban dalam lembar jawaban yang tersedia dengan melakukan sesi psikotes dengan subyek yang di tes
A4: 2 | B4: Setelah ada jawaban, buka aplikasi Skoring IST memakai excel 2010 ke atas
A5: 3 | B5: Isikan Data pribadi Peserta terlebih dahulu
A12: 4 | B12: Input jawaban klien di kolom yang disediakan, gunakan huruf kapital untuk pilihan ganda dan masukan angka exact sesuai jawaban
A13: 5 | B13: Khusus nomor 61-76 pilih opsi yang paling mendekati jawaban dari peserta, klik pada kotak jawaban untuk memilih opsi yang ada, pilih tidak cocok bila jawaban peserta tidak ada yang mendekati opsi
H15: SILAHKAN COBA: | J15: klik di Kolom ini
H16: Jawaban Peserta | J16: Opsi yang ada | K16: Skor
H17: tanaman | J17: tanaman | K17: 1
H18: Jenis bunga | J18: kembang | K18: 2
H19: akar serabut | J19: tidak cocok | K19: 0
A26: 6 | B26: Setelah terisi hasil tes akan muncul pada tabel, inilah yang dipakai untuk membuat pelaporan
A54: 7 | B54: Gunakan worksheet "Bantuan" jika anda tidak paham hasil nomor 6

Sheet IST
A1: Aplikasi Skoring IST
A2: Oleh Ebookku
AA3: 13 tahun | AK3: 14 tahun | AU3: 15 tahun | BE3: 16 tahun | BO3: 17 tahun | BY3: 18 tahun | CI3: <=20 tahun | CS3: <=24 tahun | DC3: <=28 tahun | DM3: <=33 tahun | DW3: <=39 tahun | EG3: <=45 tahun | EQ3: >45 tahun
A4: Nomor | C4: : | D4: 1 | AA4: RW | AB4: SW | AK4: RW | AL4: SW | AU4: RW | AV4: SW | BE4: RW | BF4: SW | BO4: RW | BP4: SW | BY4: RW | BZ4: SW | CI4: RW | CJ4: SW | CS4: RW | CT4: SW | DC4: RW | DD4: SW | DM4: RW | DN4: SW | DW4: RW | DX4: SW | EG4: RW | EH4: SW | EQ4: RW | ER4: SW
A5: Nama Subjek | C5: : | D5: Arman | AB5: SE | AC5: WA | AD5: AN | AE5: GE | AF5: RA | AG5: ZR | AH5: FA | AI5: WU | AJ5: ME | AL5: SE | AM5: WA | AN5: AN | AO5: GE | AP5: RA | AQ5: ZR | AR5: FA | AS5: WU | AT5: ME | AV5: SE | AW5: WA | AX5: AN | AY5: GE | AZ5: RA | BA5: ZR | BB5: FA | BC5: WU | BD5: ME | BF5: SE | BG5: WA | BH5: AN | BI5: GE | BJ5: RA | BK5: ZR | BL5: FA | BM5: WU | BN5: ME | BP5: SE | BQ5: WA | BR5: AN | BS5: GE | BT5: RA | BU5: ZR | BV5: FA | BW5: WU | BX5: ME | BZ5: SE | CA5: WA | CB5: AN | CC5: GE | CD5: RA | CE5: ZR | CF5: FA | CG5: WU | CH5: ME | CJ5: SE | CK5: WA | CL5: AN | CM5: GE | CN5: RA | CO5: ZR | CP5: FA | CQ5: WU | CR5: ME | CT5: SE | CU5: WA | CV5: AN | CW5: GE | CX5: RA | CY5: ZR | CZ5: FA | DA5: WU | DB5: ME | DD5: SE | DE5: WA | DF5: AN | DG5: GE | DH5: RA | DI5: ZR | DJ5: FA | DK5: WU | DL5: ME | DN5: SE | DO5: WA | DP5: AN | DQ5: GE | DR5: RA | DS5: ZR | DT5: FA | DU5: WU | DV5: ME | DX5: SE | DY5: WA | DZ5: AN | EA5: GE | EB5: RA | EC5: ZR | ED5: FA | EE5: WU | EF5: ME | EH5: SE | EI5: WA | EJ5: AN | EK5: GE | EL5: RA | EM5: ZR | EN5: FA | EO5: WU | EP5: ME | ER5: SE | ES5: WA | ET5: AN | EU5: GE | EV5: RA | EW5: ZR | EX5: FA | EY5: WU | EZ5: ME
A6: Tgl Lahir | C6: : | D6: 34316 | AA6: 0 | AB6: 71 | AC6: 70 | AD6: 78 | AE6: 79 | AF6: 78 | AG6: 82 | AH6: 74 | AI6: 73 | AJ6: 78 | AK6: 0 | AL6: 72 | AM6: 70 | AN6: 78 | AO6: 78 | AP6: 75 | AQ6: 82 | AR6: 75 | AS6: 73 | AT6: 70 | AU6: 0 | AV6: 73 | AW6: 70 | AX6: 78 | AY6: 82 | AZ6: 79 | BA6: 81 | BB6: 77 | BC6: 73 | BD6: 77 | BE6: 0 | BF6: 74 | BG6: 68 | BH6: 77 | BI6: 79 | BJ6: 77 | BK6: 80 | BL6: 76 | BM6: 76 | BN6: 73 | BO6: 0 | BP6: 72 | BQ6: 65 | BR6: 78 | BS6: 78 | BT6: 76 | BU6: 79 | BV6: 76 | BW6: 76 | BX6: 74 | BY6: 0 | BZ6: 72 | CA6: 64 | CB6: 76 | CC6: 75 | CD6: 75 | CE6: 79 | CF6: 74 | CG6: 74 | CH6: 73 | CI6: 0 | CJ6: 68 | CK6: 61 | CL6: 74 | CM6: 72 | CN6: 74 | CO6: 78 | CP6: 74 | CQ6: 74 | CR6: 70 | CS6: 0 | CT6: 66 | CU6: 63 | CV6: 75 | CW6: 74 | CX6: 75 | CY6: 80 | CZ6: 75 | DA6: 75 | DB6: 74 | DC6: 0 | DD6: 65 | DE6: 65 | DF6: 77 | DG6: 73 | DH6: 72 | DI6: 77 | DJ6: 74 | DK6: 74 | DL6: 77 | DM6: 0 | DN6: 65 | DO6: 65 | DP6: 78 | DQ6: 75 | DR6: 75 | DS6: 80 | DT6: 75 | DU6: 76 | DV6: 78 | DW6: 0 | DX6: 68 | DY6: 69 | DZ6: 79 | EA6: 76 | EB6: 75 | EC6: 79 | ED6: 77 | EE6: 77 | EF6: 81 | EG6: 0 | EH6: 73 | EI6: 73 | EJ6: 81 | EK6: 76 | EL6: 77 | EM6: 80 | EN6: 79 | EO6: 78 | EP6: 82 | EQ6: 0 | ER6: 75 | ES6: 75 | ET6: 82 | EU6: 77 | EV6: 77 | EW6: 81 | EX6: 80 | EY6: 78 | EZ6: 84
A7: Tgl Tes | C7: : | D7: 43754 | AA7: 1 | AB7: 75 | AC7: 74 | AD7: 81 | AE7: 82 | AF7: 81 | AG7: 85 | AH7: 78 | AI7: 77 | AJ7: 82 | AK7: 1 | AL7: 75 | AM7: 74 | AN7: 82 | AO7: 81 | AP7: 78 | AQ7: 85 | AR7: 78 | AS7: 77 | AT7: 82 | AU7: 1 | AV7: 77 | AW7: 74 | AX7: 81 | AY7: 84 | AZ7: 82 | BA7: 84 | BB7: 80 | BC7: 76 | BD7: 80 | BE7: 1 | BF7: 77 | BG7: 72 | BH7: 80 | BI7: 81 | BJ7: 80 | BK7: 83 | BL7: 79 | BM7: 79 | BN7: 76 | BO7: 1 | BP7: 75 | BQ7: 69 | BR7: 81 | BS7: 80 | BT7: 79 | BU7: 81 | BV7: 79 | BW7: 79 | BX7: 76 | BY7: 1 | BZ7: 75 | CA7: 66 | CB7: 79 | CC7: =AVERAGE(CC6,CC8) -> 76.5 | CD7: 78 | CE7: 81 | CF7: 76 | CG7: 76 | CH7: 76 | CI7: 1 | CJ7: 70 | CK7: 64 | CL7: 76 | CM7: 74 | CN7: 77 | CO7: 80 | CP7: 77 | CQ7: 77 | CR7: 73 | CS7: 1 | CT7: 68 | CU7: 66 | CV7: 78 | CW7: 76 | CX7: 77 | CY7: 82 | CZ7: 78 | DA7: 78 | DB7: 77 | DC7: 1 | DD7: 67 | DE7: 69 | DF7: 79 | DG7: 75 | DH7: 76 | DI7: 80 | DJ7: 77 | DK7: 77 | DL7: 80 | DM7: 1 | DN7: 68 | DO7: 69 | DP7: 80 | DQ7: 77 | DR7: 77 | DS7: 82 | DT7: 77 | DU7: 79 | DV7: 80 | DW7: 1 | DX7: 71 | DY7: 72 | DZ7: 81 | EA7: 78 | EB7: 77 | EC7: 81 | ED7: 80 | EE7: 80 | EF7: 83 | EG7: 1 | EH7: 75 | EI7: 76 | EJ7: 83 | EK7: 78 | EL7: 79 | EM7: 82 | EN7: 81 | EO7: 81 | EP7: 84 | EQ7: 1 | ER7: 78 | ES7: 78 | ET7: 85 | EU7: 79 | EV7: 79 | EW7: 83 | EX7: 82 | EY7: 81 | EZ7: 86
A8: Usia | C8: : | D8: =YEAR(D7)-YEAR(D6) -> 26 | E8: th | AA8: 2 | AB8: 79 | AC8: 78 | AD8: 85 | AE8: 84 | AF8: 85 | AG8: 88 | AH8: 82 | AI8: 80 | AJ8: 85 | AK8: 2 | AL8: 79 | AM8: 78 | AN8: 85 | AO8: 83 | AP8: 82 | AQ8: 88 | AR8: 81 | AS8: 80 | AT8: 85 | AU8: 2 | AV8: 80 | AW8: 77 | AX8: 84 | AY8: 86 | AZ8: 85 | BA8: 87 | BB8: 83 | BC8: 79 | BD8: 82 | BE8: 2 | BF8: 80 | BG8: 75 | BH8: 83 | BI8: 82 | BJ8: 83 | BK8: 85 | BL8: 82 | BM8: 82 | BN8: 79 | BO8: 2 | BP8: 78 | BQ8: 72 | BR8: 84 | BS8: 81 | BT8: 82 | BU8: 84 | BV8: 81 | BW8: 82 | BX8: 78 | BY8: 2 | BZ8: 78 | CA8: 69 | CB8: 81 | CC8: 78 | CD8: 81 | CE8: 84 | CF8: 79 | CG8: 80 | CH8: 78 | CI8: 2 | CJ8: 73 | CK8: 66 | CL8: 79 | CM8: 76 | CN8: 80 | CO8: 82 | CP8: 79 | CQ8: 80 | CR8: 76 | CS8: 2 | CT8: 71 | CU8: 69 | CV8: 80 | CW8: 77 | CX8: 80 | CY8: 84 | CZ8: 80 | DA8: 80 | DB8: 79 | DC8: 2 | DD8: 70 | DE8: 73 | DF8: 81 | DG8: 76 | DH8: 80 | DI8: 82 | DJ8: 80 | DK8: 80 | DL8: 82 | DM8: 2 | DN8: 71 | DO8: 72 | DP8: 82 | DQ8: 78 | DR8: 80 | DS8: 84 | DT8: 80 | DU8: 81 | DV8: 83 | DW8: 2 | DX8: 75 | DY8: 75 | DZ8: 83 | EA8: 79 | EB8: 80 | EC8: 83 | ED8: 82 | EE8: 82 | EF8: 86 | EG8: 2 | EH8: 78 | EI8: 80 | EJ8: 85 | EK8: 79 | EL8: 82 | EM8: 84 | EN8: 84 | EO8: 84 | EP8: 87 | EQ8: 2 | ER8: 81 | ES8: 81 | ET8: 87 | EU8: 80 | EV8: 81 | EW8: 85 | EX8: 85 | EY8: 84 | EZ8: 89
A9: Tujuan Tes | C9: : | D9: Rekrutmen | AA9: 3 | AB9: 83 | AC9: 82 | AD9: 89 | AE9: 87 | AF9: 89 | AG9: 92 | AH9: 86 | AI9: 84 | AJ9: 88 | AK9: 3 | AL9: 83 | AM9: 82 | AN9: 89 | AO9: 86 | AP9: 86 | AQ9: 91 | AR9: 84 | AS9: 84 | AT9: 88 | AU9: 3 | AV9: 83 | AW9: 81 | AX9: 88 | AY9: 88 | AZ9: 88 | BA9: 90 | BB9: 85 | BC9: 83 | BD9: 85 | BE9: 3 | BF9: 83 | BG9: 79 | BH9: 86 | BI9: 84 | BJ9: 86 | BK9: 88 | BL9: 85 | BM9: 85 | BN9: 82 | BO9: 3 | BP9: 81 | BQ9: 76 | BR9: 86 | BS9: 83 | BT9: 85 | BU9: 86 | BV9: 84 | BW9: 85 | BX9: 81 | BY9: 3 | BZ9: 81 | CA9: 73 | CB9: 83 | CC9: =AVERAGE(CC8,CC10) -> 80 | CD9: 84 | CE9: 86 | CF9: 82 | CG9: 83 | CH9: 80 | CI9: 3 | CJ9: 76 | CK9: 70 | CL9: 81 | CM9: 78 | CN9: 83 | CO9: 85 | CP9: 82 | CQ9: 83 | CR9: 78 | CS9: 3 | CT9: 74 | CU9: 73 | CV9: 83 | CW9: 79 | CX9: 83 | CY9: 86 | CZ9: 83 | DA9: 83 | DB9: 81 | DC9: 3 | DD9: 73 | DE9: 75 | DF9: 84 | DG9: 78 | DH9: 82 | DI9: 85 | DJ9: 82 | DK9: 83 | DL9: 84 | DM9: 3 | DN9: 74 | DO9: 75 | DP9: 84 | DQ9: 80 | DR9: 83 | DS9: 86 | DT9: 83 | DU9: 84 | DV9: 85 | DW9: 3 | DX9: 77 | DY9: 78 | DZ9: 86 | EA9: 81 | EB9: 83 | EC9: 86 | ED9: 85 | EE9: 85 | EF9: 88 | EG9: 3 | EH9: 81 | EI9: 83 | EJ9: 88 | EK9: 81 | EL9: 85 | EM9: 86 | EN9: 86 | EO9: 86 | EP9: 89 | EQ9: 3 | ER9: 84 | ES9: 84 | ET9: 89 | EU9: 81 | EV9: 84 | EW9: 88 | EX9: 88 | EY9: 87 | EZ9: 91
AA10: 4 | AB10: 87 | AC10: 86 | AD10: 93 | AE10: 89 | AF10: 93 | AG10: 95 | AH10: 89 | AI10: 88 | AJ10: 91 | AK10: 4 | AL10: 87 | AM10: 86 | AN10: 92 | AO10: 88 | AP10: 90 | AQ10: 94 | AR10: 87 | AS10: 87 | AT10: 92 | AU10: 4 | AV10: 87 | AW10: 84 | AX10: 91 | AY10: 89 | AZ10: 91 | BA10: 92 | BB10: 87 | BC10: 86 | BD10: 87 | BE10: 4 | BF10: 86 | BG10: 82 | BH10: 89 | BI10: 86 | BJ10: 89 | BK10: 90 | BL10: 87 | BM10: 88 | BN10: 84 | BO10: 4 | BP10: 84 | BQ10: 80 | BR10: 88 | BS10: 84 | BT10: 88 | BU10: 89 | BV10: 87 | BW10: 88 | BX10: 83 | BY10: 4 | BZ10: 83 | CA10: 77 | CB10: 86 | CC10: 82 | CD10: 86 | CE10: 88 | CF10: 85 | CG10: 86 | CH10: 83 | CI10: 4 | CJ10: 79 | CK10: 74 | CL10: 84 | CM10: 79 | CN10: 86 | CO10: 87 | CP10: 85 | CQ10: 86 | CR10: 81 | CS10: 4 | CT10: 78 | CU10: 76 | CV10: 85 | CW10: 80 | CX10: 86 | CY10: 89 | CZ10: 85 | DA10: 86 | DB10: 84 | DC10: 4 | DD10: 76 | DE10: 79 | DF10: 86 | DG10: 80 | DH10: 84 | DI10: 87 | DJ10: 85 | DK10: 85 | DL10: 86 | DM10: 4 | DN10: 78 | DO10: 79 | DP10: 86 | DQ10: 81 | DR10: 85 | DS10: 89 | DT10: 85 | DU10: 87 | DV10: 87 | DW10: 4 | DX10: 80 | DY10: 81 | DZ10: 89 | EA10: 82 | EB10: 86 | EC10: 88 | ED10: 87 | EE10: 87 | EF10: 90 | EG10: 4 | EH10: 84 | EI10: 85 | EJ10: 90 | EK10: 82 | EL10: 88 | EM10: 89 | EN10: 89 | EO10: 89 | EP10: 91 | EQ10: 4 | ER10: 87 | ES10: 87 | ET10: 91 | EU10: 82 | EV10: 88 | EW10: 90 | EX10: 91 | EY10: 89 | EZ10: 93
AA11: 5 | AB11: 91 | AC11: 90 | AD11: 96 | AE11: 92 | AF11: 96 | AG11: 98 | AH11: 93 | AI11: 91 | AJ11: 94 | AK11: 5 | AL11: 91 | AM11: 89 | AN11: 96 | AO11: 90 | AP11: 93 | AQ11: 97 | AR11: 91 | AS11: 90 | AT11: 94 | AU11: 5 | AV11: 90 | AW11: 88 | AX11: 94 | AY11: 91 | AZ11: 94 | BA11: 95 | BB11: 90 | BC11: 90 | BD11: 90 | BE11: 5 | BF11: 89 | BG11: 86 | BH11: 92 | BI11: 88 | BJ11: 92 | BK11: 92 | BL11: 90 | BM11: 91 | BN11: 87 | BO11: 5 | BP11: 87 | BQ11: 84 | BR11: 91 | BS11: 86 | BT11: 91 | BU11: 91 | BV11: 89 | BW11: 90 | BX11: 86 | BY11: 5 | BZ11: 86 | CA11: 81 | CB11: 89 | CC11: =AVERAGE(CC10,CC12) -> 83.5 | CD11: 89 | CE11: 91 | CF11: 88 | CG11: 89 | CH11: 85 | CI11: 5 | CJ11: 82 | CK11: 78 | CL11: 86 | CM11: 81 | CN11: 89 | CO11: 90 | CP11: 87 | CQ11: 89 | CR11: 83 | CS11: 5 | CT11: 80 | CU11: 80 | CV11: 88 | CW11: 82 | CX11: 88 | CY11: 91 | CZ11: 88 | DA11: 89 | DB11: 86 | DC11: 5 | DD11: 79 | DE11: 82 | DF11: 88 | DG11: 82 | DH11: 87 | DI11: 90 | DJ11: 88 | DK11: 88 | DL11: 89 | DM11: 5 | DN11: 81 | DO11: 82 | DP11: 88 | DQ11: 83 | DR11: 88 | DS11: 91 | DT11: 88 | DU11: 90 | DV11: 89 | DW11: 5 | DX11: 83 | DY11: 85 | DZ11: 91 | EA11: 84 | EB11: 88 | EC11: 90 | ED11: 90 | EE11: 90 | EF11: 92 | EG11: 5 | EH11: 87 | EI11: 89 | EJ11: 92 | EK11: 84 | EL11: 90 | EM11: 91 | EN11: 91 | EO11: 91 | EP11: 93 | EQ11: 5 | ER11: 90 | ES11: 90 | ET11: 94 | EU11: 84 | EV11: 91 | EW11: 92 | EX11: 93 | EY11: 92 | EZ11: 95
AA12: 6 | AB12: 95 | AC12: 94 | AD12: 100 | AE12: 94 | AF12: 100 | AG12: 101 | AH12: 95 | AI12: 95 | AJ12: 97 | AK12: 6 | AL12: 95 | AM12: 93 | AN12: 100 | AO12: 92 | AP12: 97 | AQ12: 100 | AR12: 94 | AS12: 94 | AT12: 97 | AU12: 6 | AV12: 93 | AW12: 91 | AX12: 97 | AY12: 93 | AZ12: 97 | BA12: 98 | BB12: 93 | BC12: 93 | BD12: 92 | BE12: 6 | BF12: 92 | BG12: 89 | BH12: 95 | BI12: 89 | BJ12: 95 | BK12: 95 | BL12: 92 | BM12: 94 | BN12: 90 | BO12: 6 | BP12: 90 | BQ12: 87 | BR12: 94 | BS12: 87 | BT12: 93 | BU12: 94 | BV12: 93 | BW12: 93 | BX12: 88 | BY12: 6 | BZ12: 89 | CA12: 85 | CB12: 91 | CC12: 85 | CD12: 92 | CE12: 93 | CF12: 90 | CG12: 92 | CH12: 88 | CI12: 6 | CJ12: 85 | CK12: 81 | CL12: 89 | CM12: 83 | CN12: 91 | CO12: 92 | CP12: 90 | CQ12: 91 | CR12: 86 | CS12: 6 | CT12: 83 | CU12: 83 | CV12: 90 | CW12: 83 | CX12: 91 | CY12: 93 | CZ12: 91 | DA12: 92 | DB12: 88 | DC12: 6 | DD12: 82 | DE12: 85 | DF12: 91 | DG12: 83 | DH12: 90 | DI12: 92 | DJ12: 90 | DK12: 91 | DL12: 91 | DM12: 6 | DN12: 82 | DO12: 85 | DP12: 90 | DQ12: 84 | DR12: 91 | DS12: 93 | DT12: 91 | DU12: 92 | DV12: 92 | DW12: 6 | DX12: 86 | DY12: 88 | DZ12: 93 | EA12: 85 | EB12: 91 | EC12: 92 | ED12: 93 | EE12: 93 | EF12: 94 | EG12: 6 | EH12: 90 | EI12: 92 | EJ12: 94 | EK12: 85 | EL12: 93 | EM12: 93 | EN12: 93 | EO12: 95 | EP12: 96 | EQ12: 6 | ER12: 93 | ES12: 94 | ET12: 96 | EU12: 85 | EV12: 94 | EW12: 94 | EX12: 96 | EY12: 95 | EZ12: 98
B13: Perhatian: Petugas Skoring hanya boleh mengisi di dalam tabel! | AA13: 7 | AB13: 99 | AC13: 98 | AD13: 104 | AE13: 97 | AF13: 104 | AG13: 104 | AH13: 98 | AI13: 98 | AJ13: 100 | AK13: 7 | AL13: 98 | AM13: 97 | AN13: 103 | AO13: 95 | AP13: 101 | AQ13: 103 | AR13: 97 | AS13: 97 | AT13: 100 | AU13: 7 | AV13: 97 | AW13: 95 | AX13: 100 | AY13: 95 | AZ13: 100 | BA13: 101 | BB13: 96 | BC13: 97 | BD13: 95 | BE13: 7 | BF13: 95 | BG13: 93 | BH13: 97 | BI13: 91 | BJ13: 98 | BK13: 98 | BL13: 95 | BM13: 97 | BN13: 92 | BO13: 7 | BP13: 93 | BQ13: 91 | BR13: 96 | BS13: 89 | BT13: 96 | BU13: 96 | BV13: 95 | BW13: 96 | BX13: 91 | BY13: 7 | BZ13: 92 | CA13: 89 | CB13: 94 | CC13: =AVERAGE(CC12,CC14) -> 87 | CD13: 95 | CE13: 95 | CF13: 93 | CG13: 94 | CH13: 90 | CI13: 7 | CJ13: 87 | CK13: 85 | CL13: 91 | CM13: 85 | CN13: 93 | CO13: 94 | CP13: 92 | CQ13: 94 | CR13: 89 | CS13: 7 | CT13: 86 | CU13: 87 | CV13: 92 | CW13: 85 | CX13: 94 | CY13: 95 | CZ13: 93 | DA13: 95 | DB13: 91 | DC13: 7 | DD13: 86 | DE13: 89 | DF13: 93 | DG13: 85 | DH13: 93 | DI13: 94 | DJ13: 93 | DK13: 94 | DL13: 93 | DM13: 7 | DN13: 86 | DO13: 89 | DP13: 93 | DQ13: 86 | DR13: 93 | DS13: 95 | DT13: 93 | DU13: 95 | DV13: 94 | DW13: 7 | DX13: 89 | DY13: 91 | DZ13: 95 | EA13: 86 | EB13: 94 | EC13: 95 | ED13: 95 | EE13: 96 | EF13: 97 | EG13: 7 | EH13: 92 | EI13: 95 | EJ13: 97 | EK13: 87 | EL13: 96 | EM13: 95 | EN13: 97 | EO13: 97 | EP13: 98 | EQ13: 7 | ER13: 96 | ES13: 97 | ET13: 98 | EU13: 87 | EV13: 97 | EW13: 97 | EX13: 98 | EY13: 98 | EZ13: 100
R14: HASIL TES | AA14: 8 | AB14: 103 | AC14: 102 | AD14: 107 | AE14: 99 | AF14: 107 | AG14: 108 | AH14: 101 | AI14: 102 | AJ14: 103 | AK14: 8 | AL14: 102 | AM14: 100 | AN14: 106 | AO14: 97 | AP14: 105 | AQ14: 106 | AR14: 100 | AS14: 100 | AT14: 103 | AU14: 8 | AV14: 101 | AW14: 99 | AX14: 104 | AY14: 96 | AZ14: 103 | BA14: 103 | BB14: 99 | BC14: 100 | BD14: 97 | BE14: 8 | BF14: 98 | BG14: 97 | BH14: 100 | BI14: 92 | BJ14: 100 | BK14: 100 | BL14: 98 | BM14: 100 | BN14: 95 | BO14: 8 | BP14: 96 | BQ14: 95 | BR14: 99 | BS14: 90 | BT14: 99 | BU14: 99 | BV14: 97 | BW14: 99 | BX14: 93 | BY14: 8 | BZ14: 94 | CA14: 92 | CB14: 96 | CC14: 89 | CD14: 98 | CE14: 98 | CF14: 96 | CG14: 97 | CH14: 92 | CI14: 8 | CJ14: 90 | CK14: 89 | CL14: 93 | CM14: 86 | CN14: 97 | CO14: 96 | CP14: 95 | CQ14: 97 | CR14: 91 | CS14: 8 | CT14: 89 | CU14: 91 | CV14: 95 | CW14: 86 | CX14: 97 | CY14: 97 | CZ14: 96 | DA14: 97 | DB14: 93 | DC14: 8 | DD14: 89 | DE14: 92 | DF14: 95 | DG14: 87 | DH14: 96 | DI14: 97 | DJ14: 96 | DK14: 97 | DL14: 95 | DM14: 8 | DN14: 89 | DO14: 92 | DP14: 96 | DQ14: 87 | DR14: 96 | DS14: 97 | DT14: 95 | DU14: 98 | DV14: 97 | DW14: 8 | DX14: 92 | DY14: 94 | DZ14: 97 | EA14: 87 | EB14: 97 | EC14: 97 | ED14: 98 | EE14: 98 | EF14: 99 | EG14: 8 | EH14: 95 | EI14: 98 | EJ14: 99 | EK14: 88 | EL14: 98 | EM14: 98 | EN14: 99 | EO14: 100 | EP14: 100 | EQ14: 8 | ER14: 99 | ES14: 100 | ET14: 101 | EU14: 88 | EV14: 99 | EW14: 99 | EX14: 101 | EY14: 101 | EZ14: 102
B15: SE | E15: WA | H15: AN | K15: GE | N15: RA | AA15: 9 | AB15: 107 | AC15: 106 | AD15: 111 | AE15: 102 | AF15: 111 | AG15: 111 | AH15: 105 | AI15: 105 | AJ15: 107 | AK15: 9 | AL15: 106 | AM15: 104 | AN15: 110 | AO15: 100 | AP15: 109 | AQ15: 109 | AR15: 104 | AS15: 104 | AT15: 106 | AU15: 9 | AV15: 104 | AW15: 102 | AX15: 107 | AY15: 98 | AZ15: 106 | BA15: 106 | BB15: 102 | BC15: 103 | BD15: 100 | BE15: 9 | BF15: 101 | BG15: 100 | BH15: 103 | BI15: 94 | BJ15: 104 | BK15: 103 | BL15: 100 | BM15: 102 | BN15: 97 | BO15: 9 | BP15: 99 | BQ15: 98 | BR15: 101 | BS15: 92 | BT15: 102 | BU15: 101 | BV15: 100 | BW15: 102 | BX15: 96 | BY15: 9 | BZ15: 97 | CA15: 96 | CB15: 99 | CC15: =AVERAGE(CC14,CC16) -> 91 | CD15: 101 | CE15: 100 | CF15: 99 | CG15: 100 | CH15: 95 | CI15: 9 | CJ15: 93 | CK15: 93 | CL15: 97 | CM15: 88 | CN15: 100 | CO15: 99 | CP15: 98 | CQ15: 100 | CR15: 93 | CS15: 9 | CT15: 92 | CU15: 95 | CV15: 97 | CW15: 88 | CX15: 99 | CY15: 99 | CZ15: 98 | DA15: 100 | DB15: 95 | DC15: 9 | DD15: 92 | DE15: 95 | DF15: 98 | DG15: 89 | DH15: 98 | DI15: 99 | DJ15: 99 | DK15: 100 | DL15: 98 | DM15: 9 | DN15: 92 | DO15: 96 | DP15: 98 | DQ15: 89 | DR15: 99 | DS15: 100 | DT15: 99 | DU15: 101 | DV15: 99 | DW15: 9 | DX15: 95 | DY15: 97 | DZ15: 100 | EA15: 89 | EB15: 99 | EC15: 99 | ED15: 101 | EE15: 101 | EF15: 101 | EG15: 9 | EH15: 98 | EI15: 101 | EJ15: 101 | EK15: 90 | EL15: 101 | EM15: 100 | EN15: 102 | EO15: 103 | EP15: 102 | EQ15: 9 | ER15: 102 | ES15: 103 | ET15: 103 | EU15: 90 | EV15: 102 | EW15: 101 | EX15: 104 | EY15: 103 | EZ15: 105
B16: No | C16: Jawaban Subjek | E16: No | F16: Jawaban Subjek | H16: No | I16: Jawaban Subjek | K16: No | L16: Jawaban Subjek | N16: No | O16: Jawaban Subjek | S16: Laporan Hasil Skoring | AA16: 10 | AB16: 110 | AC16: 110 | AD16: 115 | AE16: 104 | AF16: 115 | AG16: 114 | AH16: 108 | AI16: 109 | AJ16: 110 | AK16: 10 | AL16: 110 | AM16: 108 | AN16: 113 | AO16: 102 | AP16: 112 | AQ16: 112 | AR16: 107 | AS16: 108 | AT16: 110 | AU16: 10 | AV16: 107 | AW16: 106 | AX16: 110 | AY16: 100 | AZ16: 109 | BA16: 109 | BB16: 104 | BC16: 106 | BD16: 103 | BE16: 10 | BF16: 104 | BG16: 104 | BH16: 106 | BI16: 95 | BJ16: 107 | BK16: 105 | BL16: 103 | BM16: 105 | BN16: 100 | BO16: 10 | BP16: 102 | BQ16: 102 | BR16: 104 | BS16: 93 | BT16: 105 | BU16: 104 | BV16: 103 | BW16: 105 | BX16: 98 | BY16: 10 | BZ16: 100 | CA16: 100 | CB16: 101 | CC16: 93 | CD16: 104 | CE16: 102 | CF16: 101 | CG16: 103 | CH16: 97 | CI16: 10 | CJ16: 96 | CK16: 97 | CL16: 99 | CM16: 89 | CN16: 103 | CO16: 101 | CP16: 100 | CQ16: 103 | CR16: 96 | CS16: 10 | CT16: 95 | CU16: 98 | CV16: 100 | CW16: 89 | CX16: 102 | CY16: 102 | CZ16: 101 | DA16: 103 | DB16: 98 | DC16: 10 | DD16: 95 | DE16: 99 | DF16: 100 | DG16: 90 | DH16: 101 | DI16: 101 | DJ16: 101 | DK16: 103 | DL16: 100 | DM16: 10 | DN16: 93 | DO16: 100 | DP16: 100 | DQ16: 90 | DR16: 102 | DS16: 102 | DT16: 101 | DU16: 104 | DV16: 101 | DW16: 10 | DX16: 98 | DY16: 101 | DZ16: 102 | EA16: 90 | EB16: 102 | EC16: 102 | ED16: 103 | EE16: 104 | EF16: 103 | EG16: 10 | EH16: 101 | EI16: 104 | EJ16: 103 | EK16: 91 | EL16: 104 | EM16: 102 | EN16: 104 | EO16: 105 | EP16: 104 | EQ16: 10 | ER16: 104 | ES16: 106 | ET16: 105 | EU16: 91 | EV16: 104 | EW16: 103 | EX16: 106 | EY16: 106 | EZ16: 107
AA17: 11 | AB17: 115 | AC17: 114 | AD17: 119 | AE17: 107 | AF17: 119 | AG17: 117 | AH17: 112 | AI17: 112 | AJ17: 113 | AK17: 11 | AL17: 114 | AM17: 112 | AN17: 117 | AO17: 105 | AP17: 116 | AQ17: 115 | AR17: 110 | AS17: 111 | AT17: 112 | AU17: 11 | AV17: 111 | AW17: 109 | AX17: 113 | AY17: 102 | AZ17: 112 | BA17: 112 | BB17: 107 | BC17: 110 | BD17: 105 | BE17: 11 | BF17: 107 | BG17: 107 | BH17: 109 | BI17: 97 | BJ17: 110 | BK17: 108 | BL17: 106 | BM17: 108 | BN17: 102 | BO17: 11 | BP17: 105 | BQ17: 106 | BR17: 106 | BS17: 95 | BT17: 108 | BU17: 106 | BV17: 105 | BW17: 107 | BX17: 101 | BY17: 11 | BZ17: 103 | CA17: 104 | CB17: 104 | CC17: =AVERAGE(CC16,CC18) -> 94 | CD17: 107 | CE17: 105 | CF17: 104 | CG17: 106 | CH17: 99 | CI17: 11 | CJ17: 99 | CK17: 101 | CL17: 102 | CM17: 91 | CN17: 106 | CO17: 104 | CP17: 103 | CQ17: 106 | CR17: 98 | CS17: 11 | CT17: 98 | CU17: 102 | CV17: 102 | CW17: 91 | CX17: 105 | CY17: 104 | CZ17: 103 | DA17: 106 | DB17: 100 | DC17: 11 | DD17: 98 | DE17: 102 | DF17: 102 | DG17: 91 | DH17: 104 | DI17: 104 | DJ17: 104 | DK17: 106 | DL17: 102 | DM17: 11 | DN17: 98 | DO17: 103 | DP17: 102 | DQ17: 92 | DR17: 104 | DS17: 104 | DT17: 103 | DU17: 106 | DV17: 103 | DW17: 11 | DX17: 101 | DY17: 104 | DZ17: 104 | EA17: 92 | EB17: 105 | EC17: 104 | ED17: 105 | EE17: 106 | EF17: 106 | EG17: 11 | EH17: 104 | EI17: 108 | EJ17: 106 | EK17: 93 | EL17: 106 | EM17: 104 | EN17: 107 | EO17: 108 | EP17: 107 | EQ17: 11 | ER17: 107 | ES17: 110 | ET17: 107 | EU17: 93 | EV17: 107 | EW17: 105 | EX17: 109 | EY17: 109 | EZ17: 109
B18: 1 | E18: 21 | H18: 41 | K18: 61 | L18: klik untuk pilih | N18: 77 | S18: Nomor | T18: : | U18: =IF(D4>0,D4,"") -> 1 | AA18: 12 | AB18: 119 | AC18: 117 | AD18: 122 | AE18: 109 | AF18: 122 | AG18: 120 | AH18: 115 | AI18: 116 | AJ18: 116 | AK18: 12 | AL18: 118 | AM18: 115 | AN18: 120 | AO18: 107 | AP18: 119 | AQ18: 118 | AR18: 113 | AS18: 115 | AT18: 115 | AU18: 12 | AV18: 114 | AW18: 113 | AX18: 116 | AY18: 104 | AZ18: 115 | BA18: 114 | BB18: 110 | BC18: 113 | BD18: 108 | BE18: 12 | BF18: 110 | BG18: 110 | BH18: 112 | BI18: 98 | BJ18: 113 | BK18: 110 | BL18: 109 | BM18: 111 | BN18: 105 | BO18: 12 | BP18: 108 | BQ18: 109 | BR18: 109 | BS18: 97 | BT18: 111 | BU18: 109 | BV18: 108 | BW18: 110 | BX18: 104 | BY18: 12 | BZ18: 106 | CA18: 108 | CB18: 106 | CC18: 95 | CD18: 109 | CE18: 107 | CF18: 107 | CG18: 109 | CH18: 102 | CI18: 12 | CJ18: 101 | CK18: 105 | CL18: 104 | CM18: 92 | CN18: 109 | CO18: 106 | CP18: 106 | CQ18: 109 | CR18: 101 | CS18: 12 | CT18: 101 | CU18: 106 | CV18: 104 | CW18: 92 | CX18: 107 | CY18: 106 | CZ18: 106 | DA18: 108 | DB18: 102 | DC18: 12 | DD18: 101 | DE18: 105 | DF18: 105 | DG18: 92 | DH18: 107 | DI18: 106 | DJ18: 107 | DK18: 109 | DL18: 104 | DM18: 12 | DN18: 101 | DO18: 106 | DP18: 104 | DQ18: 94 | DR18: 107 | DS18: 106 | DT18: 106 | DU18: 109 | DV18: 106 | DW18: 12 | DX18: 104 | DY18: 107 | DZ18: 106 | EA18: 93 | EB18: 109 | EC18: 106 | ED18: 108 | EE18: 109 | EF18: 108 | EG18: 12 | EH18: 107 | EI18: 111 | EJ18: 108 | EK18: 94 | EL18: 109 | EM18: 107 | EN18: 109 | EO18: 111 | EP18: 109 | EQ18: 12 | ER18: 110 | ES18: 113 | ET18: 110 | EU18: 94 | EV18: 110 | EW18: 108 | EX18: 112 | EY18: 112 | EZ18: 111
B19: 2 | E19: 22 | H19: 42 | K19: 62 | L19: klik untuk pilih | N19: 78 | S19: Nama | T19: : | U19: =IF(D5>0,D5,"") -> Arman | AA19: 13 | AB19: 123 | AC19: 122 | AD19: 126 | AE19: 112 | AF19: 126 | AG19: 124 | AH19: 119 | AI19: 120 | AJ19: 119 | AK19: 13 | AL19: 122 | AM19: 119 | AN19: 123 | AO19: 109 | AP19: 123 | AQ19: 121 | AR19: 116 | AS19: 118 | AT19: 117 | AU19: 13 | AV19: 118 | AW19: 116 | AX19: 120 | AY19: 106 | AZ19: 118 | BA19: 117 | BB19: 113 | BC19: 117 | BD19: 110 | BE19: 13 | BF19: 113 | BG19: 114 | BH19: 115 | BI19: 100 | BJ19: 116 | BK19: 112 | BL19: 111 | BM19: 114 | BN19: 108 | BO19: 13 | BP19: 111 | BQ19: 113 | BR19: 111 | BS19: 99 | BT19: 113 | BU19: 111 | BV19: 111 | BW19: 113 | BX19: 106 | BY19: 13 | BZ19: 108 | CA19: 112 | CB19: 109 | CC19: =AVERAGE(CC18,CC20) -> 96.5 | CD19: 112 | CE19: 110 | CF19: 110 | CG19: 112 | CH19: 104 | CI19: 13 | CJ19: 104 | CK19: 109 | CL19: 107 | CM19: 94 | CN19: 111 | CO19: 108 | CP19: 109 | CQ19: 111 | CR19: 103 | CS19: 13 | CT19: 104 | CU19: 109 | CV19: 107 | CW19: 94 | CX19: 110 | CY19: 108 | CZ19: 108 | DA19: 111 | DB19: 105 | DC19: 13 | DD19: 104 | DE19: 109 | DF19: 107 | DG19: 94 | DH19: 110 | DI19: 109 | DJ19: 109 | DK19: 112 | DL19: 107 | DM19: 13 | DN19: 104 | DO19: 110 | DP19: 107 | DQ19: 96 | DR19: 110 | DS19: 108 | DT19: 109 | DU19: 112 | DV19: 108 | DW19: 13 | DX19: 107 | DY19: 110 | DZ19: 108 | EA19: 95 | EB19: 111 | EC19: 108 | ED19: 110 | EE19: 112 | EF19: 110 | EG19: 13 | EH19: 110 | EI19: 114 | EJ19: 110 | EK19: 96 | EL19: 112 | EM19: 109 | EN19: 112 | EO19: 114 | EP19: 111 | EQ19: 13 | ER19: 113 | ES19: 116 | ET19: 112 | EU19: 96 | EV19: 113 | EW19: 110 | EX19: 115 | EY19: 115 | EZ19: 114
B20: 3 | E20: 23 | H20: 43 | K20: 63 | L20: klik untuk pilih | N20: 79 | S20: Tgl Lahir | T20: : | U20: =IF(D6>0,D6,"") -> 34316 | AA20: 14 | AB20: 126 | AC20: 125 | AD20: 129 | AE20: 114 | AF20: 129 | AG20: 127 | AH20: 122 | AI20: 123 | AJ20: 122 | AK20: 14 | AL20: 125 | AM20: 123 | AN20: 127 | AO20: 111 | AP20: 126 | AQ20: 124 | AR20: 120 | AS20: 122 | AT20: 120 | AU20: 14 | AV20: 121 | AW20: 120 | AX20: 123 | AY20: 107 | AZ20: 121 | BA20: 120 | BB20: 115 | BC20: 120 | BD20: 113 | BE20: 14 | BF20: 115 | BG20: 118 | BH20: 117 | BI20: 102 | BJ20: 119 | BK20: 115 | BL20: 114 | BM20: 117 | BN20: 110 | BO20: 14 | BP20: 114 | BQ20: 116 | BR20: 114 | BS20: 100 | BT20: 116 | BU20: 114 | BV20: 113 | BW20: 116 | BX20: 109 | BY20: 14 | BZ20: 111 | CA20: 115 | CB20: 112 | CC20: 98 | CD20: 115 | CE20: 112 | CF20: 113 | CG20: 115 | CH20: 106 | CI20: 14 | CJ20: 107 | CK20: 112 | CL20: 109 | CM20: 96 | CN20: 114 | CO20: 111 | CP20: 111 | CQ20: 114 | CR20: 106 | CS20: 14 | CT20: 107 | CU20: 113 | CV20: 109 | CW20: 95 | CX20: 113 | CY20: 110 | CZ20: 111 | DA20: 114 | DB20: 107 | DC20: 14 | DD20: 108 | DE20: 112 | DF20: 109 | DG20: 96 | DH20: 112 | DI20: 111 | DJ20: 112 | DK20: 115 | DL20: 109 | DM20: 14 | DN20: 107 | DO20: 113 | DP20: 109 | DQ20: 97 | DR20: 112 | DS20: 111 | DT20: 111 | DU20: 115 | DV20: 110 | DW20: 14 | DX20: 110 | DY20: 114 | DZ20: 111 | EA20: 96 | EB20: 113 | EC20: 111 | ED20: 113 | EE20: 115 | EF20: 112 | EG20: 14 | EH20: 113 | EI20: 117 | EJ20: 112 | EK20: 97 | EL20: 115 | EM20: 111 | EN20: 115 | EO20: 116 | EP20: 113 | EQ20: 14 | ER20: 116 | ES20: 119 | ET20: 114 | EU20: 97 | EV20: 116 | EW20: 112 | EX20: 117 | EY20: 117 | EZ20: 116
B21: 4 | E21: 24 | H21: 44 | K21: 64 | L21: Klik untuk pilih | N21: 80 | S21: Tgl Tes | T21: : | U21: =IF(D7>0,D7,"") -> 43754 | AA21: 15 | AB21: 131 | AC21: 129 | AD21: 133 | AE21: 117 | AF21: 133 | AG21: 130 | AH21: 125 | AI21: 126 | AJ21: 125 | AK21: 15 | AL21: 129 | AM21: 127 | AN21: 130 | AO21: 114 | AP21: 130 | AQ21: 127 | AR21: 123 | AS21: 125 | AT21: 124 | AU21: 15 | AV21: 125 | AW21: 124 | AX21: 126 | AY21: 109 | AZ21: 124 | BA21: 123 | BB21: 118 | BC21: 124 | BD21: 115 | BE21: 15 | BF21: 119 | BG21: 121 | BH21: 120 | BI21: 104 | BJ21: 122 | BK21: 118 | BL21: 117 | BM21: 120 | BN21: 113 | BO21: 15 | BP21: 116 | BQ21: 120 | BR21: 117 | BS21: 102 | BT21: 119 | BU21: 116 | BV21: 116 | BW21: 119 | BX21: 111 | BY21: 15 | BZ21: 114 | CA21: 119 | CB21: 114 | CC21: =AVERAGE(CC20,CC22) -> 100 | CD21: 118 | CE21: 114 | CF21: 115 | CG21: 118 | CH21: 109 | CI21: 15 | CJ21: 110 | CK21: 116 | CL21: 112 | CM21: 98 | CN21: 117 | CO21: 113 | CP21: 114 | CQ21: 117 | CR21: 108 | CS21: 15 | CT21: 110 | CU21: 116 | CV21: 111 | CW21: 97 | CX21: 115 | CY21: 112 | CZ21: 113 | DA21: 117 | DB21: 109 | DC21: 15 | DD21: 111 | DE21: 115 | DF21: 112 | DG21: 98 | DH21: 115 | DI21: 113 | DJ21: 115 | DK21: 118 | DL21: 111 | DM21: 15 | DN21: 110 | DO21: 117 | DP21: 111 | DQ21: 98 | DR21: 115 | DS21: 113 | DT21: 115 | DU21: 118 | DV21: 112 | DW21: 15 | DX21: 113 | DY21: 117 | DZ21: 113 | EA21: 98 | EB21: 116 | EC21: 113 | ED21: 115 | EE21: 117 | EF21: 115 | EG21: 15 | EH21: 115 | EI21: 120 | EJ21: 114 | EK21: 99 | EL21: 117 | EM21: 113 | EN21: 117 | EO21: 119 | EP21: 116 | EQ21: 15 | ER21: 119 | ES21: 123 | ET21: 116 | EU21: 99 | EV21: 119 | EW21: 114 | EX21: 119 | EY21: 120 | EZ21: 118
B22: 5 | E22: 25 | H22: 45 | K22: 65 | L22: Klik untuk pilih | N22: 81 | S22: Usia | T22: : | U22: =IF(D8>0,D8,"") -> 26 | AA22: 16 | AB22: 135 | AC22: 133 | AD22: 137 | AE22: 119 | AF22: 137 | AG22: 134 | AH22: 129 | AI22: 130 | AJ22: 128 | AK22: 16 | AL22: 133 | AM22: 130 | AN22: 134 | AO22: 116 | AP22: 134 | AQ22: 130 | AR22: 126 | AS22: 129 | AT22: 127 | AU22: 16 | AV22: 128 | AW22: 127 | AX22: 129 | AY22: 110 | AZ22: 127 | BA22: 126 | BB22: 121 | BC22: 127 | BD22: 118 | BE22: 16 | BF22: 122 | BG22: 125 | BH22: 123 | BI22: 105 | BJ22: 124 | BK22: 120 | BL22: 120 | BM22: 123 | BN22: 116 | BO22: 16 | BP22: 119 | BQ22: 124 | BR22: 119 | BS22: 103 | BT22: 122 | BU22: 119 | BV22: 119 | BW22: 122 | BX22: 114 | BY22: 16 | BZ22: 117 | CA22: 123 | CB22: 117 | CC22: 102 | CD22: 121 | CE22: 117 | CF22: 118 | CG22: 121 | CH22: 111 | CI22: 16 | CJ22: 113 | CK22: 120 | CL22: 115 | CM22: 100 | CN22: 120 | CO22: 115 | CP22: 117 | CQ22: 120 | CR22: 111 | CS22: 16 | CT22: 113 | CU22: 120 | CV22: 114 | CW22: 98 | CX22: 118 | CY22: 115 | CZ22: 116 | DA22: 120 | DB22: 112 | DC22: 16 | DD22: 114 | DE22: 119 | DF22: 114 | DG22: 99 | DH22: 118 | DI22: 116 | DJ22: 118 | DK22: 121 | DL22: 113 | DM22: 16 | DN22: 113 | DO22: 120 | DP22: 113 | DQ22: 99 | DR22: 118 | DS22: 115 | DT22: 117 | DU22: 120 | DV22: 114 | DW22: 16 | DX22: 116 | DY22: 120 | DZ22: 115 | EA22: 99 | EB22: 119 | EC22: 115 | ED22: 118 | EE22: 120 | EF22: 117 | EG22: 16 | EH22: 118 | EI22: 123 | EJ22: 117 | EK22: 100 | EL22: 120 | EM22: 115 | EN22: 120 | EO22: 122 | EP22: 118 | EQ22: 16 | ER22: 122 | ES22: 126 | ET22: 119 | EU22: 100 | EV22: 121 | EW22: 116 | EX22: 122 | EY22: 123 | EZ22: 120
B23: 6 | E23: 26 | H23: 46 | K23: 66 | L23: Klik untuk pilih | N23: 82 | S23: Tujuan Tes | T23: : | U23: =IF(D9>0,D9,"") -> Rekrutmen | AA23: 17 | AB23: 138 | AC23: 137 | AD23: 140 | AE23: 122 | AF23: 140 | AG23: 137 | AH23: 132 | AI23: 133 | AJ23: 131 | AK23: 17 | AL23: 137 | AM23: 134 | AN23: 137 | AO23: 119 | AP23: 137 | AQ23: 133 | AR23: 129 | AS23: 132 | AT23: 129 | AU23: 17 | AV23: 131 | AW23: 131 | AX23: 133 | AY23: 112 | AZ23: 130 | BA23: 129 | BB23: 124 | BC23: 130 | BD23: 120 | BE23: 17 | BF23: 125 | BG23: 128 | BH23: 126 | BI23: 107 | BJ23: 127 | BK23: 123 | BL23: 122 | BM23: 126 | BN23: 118 | BO23: 17 | BP23: 122 | BQ23: 128 | BR23: 122 | BS23: 105 | BT23: 125 | BU23: 121 | BV23: 121 | BW23: 124 | BX23: 116 | BY23: 17 | BZ23: 119 | CA23: 127 | CB23: 119 | CC23: =AVERAGE(CC22,CC24) -> 103.5 | CD23: 124 | CE23: 119 | CF23: 121 | CG23: 123 | CH23: 113 | CI23: 17 | CJ23: 116 | CK23: 124 | CL23: 117 | CM23: 101 | CN23: 123 | CO23: 118 | CP23: 120 | CQ23: 123 | CR23: 113 | CS23: 17 | CT23: 116 | CU23: 124 | CV23: 116 | CW23: 100 | CX23: 121 | CY23: 117 | CZ23: 119 | DA23: 122 | DB23: 114 | DC23: 17 | DD23: 117 | DE23: 122 | DF23: 116 | DG23: 101 | DH23: 120 | DI23: 118 | DJ23: 120 | DK23: 123 | DL23: 116 | DM23: 17 | DN23: 116 | DO23: 123 | DP23: 116 | DQ23: 101 | DR23: 121 | DS23: 117 | DT23: 120 | DU23: 123 | DV23: 117 | DW23: 17 | DX23: 119 | DY23: 123 | DZ23: 117 | EA23: 101 | EB23: 122 | EC23: 117 | ED23: 120 | EE23: 123 | EF23: 120 | EG23: 17 | EH23: 121 | EI23: 126 | EJ23: 119 | EK23: 102 | EL23: 123 | EM23: 118 | EN23: 122 | EO23: 124 | EP23: 120 | EQ23: 17 | ER23: 125 | ES23: 129 | ET23: 121 | EU23: 102 | EV23: 125 | EW23: 118 | EX23: 125 | EY23: 125 | EZ23: 123
B24: 7 | E24: 27 | H24: 47 | K24: 67 | L24: Klik untuk pilih | N24: 83 | AA24: 18 | AB24: 142 | AC24: 141 | AD24: 144 | AE24: 124 | AF24: 144 | AG24: 140 | AH24: 135 | AI24: 137 | AJ24: 134 | AK24: 18 | AL24: 141 | AM24: 138 | AN24: 140 | AO24: 121 | AP24: 140 | AQ24: 136 | AR24: 132 | AS24: 135 | AT24: 132 | AU24: 18 | AV24: 135 | AW24: 134 | AX24: 136 | AY24: 113 | AZ24: 133 | BA24: 132 | BB24: 127 | BC24: 133 | BD24: 123 | BE24: 18 | BF24: 128 | BG24: 132 | BH24: 129 | BI24: 108 | BJ24: 129 | BK24: 126 | BL24: 125 | BM24: 129 | BN24: 121 | BO24: 18 | BP24: 125 | BQ24: 131 | BR24: 124 | BS24: 106 | BT24: 127 | BU24: 124 | BV24: 125 | BW24: 127 | BX24: 119 | BY24: 18 | BZ24: 122 | CA24: 131 | CB24: 122 | CC24: 105 | CD24: 126 | CE24: 122 | CF24: 124 | CG24: 126 | CH24: 116 | CI24: 18 | CJ24: 119 | CK24: 127 | CL24: 120 | CM24: 102 | CN24: 126 | CO24: 120 | CP24: 122 | CQ24: 126 | CR24: 116 | CS24: 18 | CT24: 119 | CU24: 128 | CV24: 119 | CW24: 102 | CX24: 123 | CY24: 119 | CZ24: 121 | DA24: 125 | DB24: 116 | DC24: 18 | DD24: 120 | DE24: 125 | DF24: 119 | DG24: 102 | DH24: 123 | DI24: 120 | DJ24: 123 | DK24: 126 | DL24: 118 | DM24: 18 | DN24: 119 | DO24: 127 | DP24: 118 | DQ24: 102 | DR24: 124 | DS24: 120 | DT24: 123 | DU24: 126 | DV24: 119 | DW24: 18 | DX24: 121 | DY24: 126 | DZ24: 120 | EA24: 102 | EB24: 124 | EC24: 120 | ED24: 123 | EE24: 125 | EF24: 122 | EG24: 18 | EH24: 124 | EI24: 130 | EJ24: 121 | EK24: 103 | EL24: 125 | EM24: 120 | EN24: 125 | EO24: 127 | EP24: 122 | EQ24: 18 | ER24: 128 | ES24: 132 | ET24: 123 | EU24: 103 | EV24: 128 | EW24: 120 | EX24: 128 | EY24: 129 | EZ24: 125
B25: 8 | E25: 28 | H25: 48 | K25: 68 | L25: Klik untuk pilih | N25: 84 | AA25: 19 | AB25: 146 | AC25: 145 | AD25: 148 | AE25: 127 | AF25: 148 | AG25: 143 | AH25: 139 | AI25: 141 | AJ25: 138 | AK25: 19 | AL25: 145 | AM25: 142 | AN25: 144 | AO25: 124 | AP25: 144 | AQ25: 139 | AR25: 135 | AS25: 139 | AT25: 135 | AU25: 19 | AV25: 138 | AW25: 138 | AX25: 139 | AY25: 115 | AZ25: 136 | BA25: 135 | BB25: 130 | BC25: 136 | BD25: 126 | BE25: 19 | BF25: 131 | BG25: 136 | BH25: 132 | BI25: 110 | BJ25: 133 | BK25: 129 | BL25: 127 | BM25: 132 | BN25: 124 | BO25: 19 | BP25: 128 | BQ25: 135 | BR25: 127 | BS25: 108 | BT25: 130 | BU25: 126 | BV25: 127 | BW25: 130 | BX25: 121 | BY25: 19 | BZ25: 125 | CA25: 135 | CB25: 125 | CC25: =AVERAGE(CC24,CC26) -> 106.5 | CD25: 129 | CE25: 124 | CF25: 127 | CG25: 129 | CH25: 118 | CI25: 19 | CJ25: 122 | CK25: 132 | CL25: 122 | CM25: 104 | CN25: 128 | CO25: 123 | CP25: 125 | CQ25: 128 | CR25: 118 | CS25: 19 | CT25: 123 | CU25: 131 | CV25: 121 | CW25: 104 | CX25: 126 | CY25: 121 | CZ25: 124 | DA25: 128 | DB25: 119 | DC25: 19 | DD25: 123 | DE25: 129 | DF25: 121 | DG25: 104 | DH25: 126 | DI25: 123 | DJ25: 126 | DK25: 130 | DL25: 120 | DM25: 19 | DN25: 122 | DO25: 130 | DP25: 120 | DQ25: 103 | DR25: 126 | DS25: 122 | DT25: 127 | DU25: 129 | DV25: 122 | DW25: 19 | DX25: 124 | DY25: 130 | DZ25: 122 | EA25: 104 | EB25: 127 | EC25: 122 | ED25: 126 | EE25: 128 | EF25: 124 | EG25: 19 | EH25: 127 | EI25: 133 | EJ25: 123 | EK25: 105 | EL25: 128 | EM25: 122 | EN25: 128 | EO25: 130 | EP25: 125 | EQ25: 19 | ER25: 131 | ES25: 135 | ET25: 126 | EU25: 105 | EV25: 131 | EW25: 123 | EX25: 131 | EY25: 131 | EZ25: 127
B26: 9 | E26: 29 | H26: 49 | K26: 69 | L26: Klik untuk pilih | N26: 85 | U26: RW | V26: SW | W26: Kategori | AA26: 20 | AB26: 151 | AC26: 150 | AD26: 152 | AE26: 129 | AF26: 152 | AG26: 147 | AH26: 142 | AI26: 145 | AJ26: 141 | AK26: 20 | AL26: 149 | AM26: 146 | AN26: 147 | AO26: 126 | AP26: 147 | AQ26: 143 | AR26: 139 | AS26: 142 | AT26: 138 | AU26: 20 | AV26: 142 | AW26: 141 | AX26: 142 | AY26: 117 | AZ26: 140 | BA26: 138 | BB26: 133 | BC26: 140 | BD26: 128 | BE26: 20 | BF26: 134 | BG26: 139 | BH26: 135 | BI26: 111 | BJ26: 137 | BK26: 131 | BL26: 130 | BM26: 135 | BN26: 126 | BO26: 20 | BP26: 131 | BQ26: 139 | BR26: 130 | BS26: 110 | BT26: 134 | BU26: 129 | BV26: 130 | BW26: 133 | BX26: 123 | BY26: 20 | BZ26: 128 | CA26: 138 | CB26: 127 | CC26: 108 | CD26: 132 | CE26: 126 | CF26: 130 | CG26: 132 | CH26: 121 | CI26: 20 | CJ26: 124 | CK26: 135 | CL26: 125 | CM26: 106 | CN26: 131 | CO26: 125 | CP26: 128 | CQ26: 131 | CR26: 121 | CS26: 20 | CT26: 126 | CU26: 135 | CV26: 123 | CW26: 105 | CX26: 129 | CY26: 124 | CZ26: 127 | DA26: 131 | DB26: 121 | DC26: 20 | DD26: 126 | DE26: 132 | DF26: 123 | DG26: 105 | DH26: 130 | DI26: 127 | DJ26: 130 | DK26: 133 | DL26: 122 | DM26: 20 | DN26: 126 | DO26: 134 | DP26: 122 | DQ26: 104 | DR26: 129 | DS26: 124 | DT26: 128 | DU26: 131 | DV26: 124 | DW26: 20 | DX26: 128 | DY26: 133 | DZ26: 124 | EA26: 105 | EB26: 130 | EC26: 124 | ED26: 128 | EE26: 131 | EF26: 127 | EG26: 20 | EH26: 130 | EI26: 136 | EJ26: 126 | EK26: 106 | EL26: 131 | EM26: 125 | EN26: 130 | EO26: 133 | EP26: 127 | EQ26: 20 | ER26: 134 | ES26: 139 | ET26: 129 | EU26: 106 | EV26: 134 | EW26: 125 | EX26: 133 | EY26: 134 | EZ26: 130
B27: 10 | E27: 30 | H27: 50 | K27: 70 | L27: Klik untuk pilih | N27: 86 | T27: SE | U27: =C93 -> 0 | V27: =IF($D$8<=20,AU45,AV45) -> 65 | W27: =IF(V27<=80,"Sangat Rendah",IF(V27<=94,"Rendah",IF(V27<=99,"Sedang",IF(V27<=104,"Cukup",IF(V27<=118,"Tinggi","Sangat Tinggi"))))) -> Sangat Rendah | AA27: 21 | AE27: 132 | AK27: 21 | AO27: 128 | AU27: 21 | AY27: 119 | BE27: 21 | BI27: 113 | BO27: 21 | BS27: 112 | BY27: 21 | CC27: =AVERAGE(CC26,CC28) -> 109.5 | CI27: 21 | CM27: 108 | CS27: 21 | CW27: 107 | DC27: 21 | DG27: 107 | DM27: 21 | DQ27: 106 | DW27: 21 | EA27: 107 | EG27: 21 | EK27: 108 | EQ27: 21 | EU27: 108
B28: 11 | E28: 31 | H28: 51 | K28: 71 | L28: Klik untuk pilih | N28: 87 | T28: WA | U28: =F93 -> 0 | V28: =IF($D$8<=20,AU46,AV46) -> 65 | W28: =IF(V28<=80,"Sangat Rendah",IF(V28<=94,"Rendah",IF(V28<=99,"Sedang",IF(V28<=104,"Cukup",IF(V28<=118,"Tinggi","Sangat Tinggi"))))) -> Sangat Rendah | AA28: 22 | AE28: 134 | AK28: 22 | AO28: 130 | AU28: 22 | AY28: 120 | BE28: 22 | BI28: 114 | BO28: 22 | BS28: 113 | BY28: 22 | CC28: 111 | CI28: 22 | CM28: 109 | CS28: 22 | CW28: 108 | DC28: 22 | DG28: 108 | DM28: 22 | DQ28: 107 | DW28: 22 | EA28: 108 | EG28: 22 | EK28: 109 | EQ28: 22 | EU28: 109
B29: 12 | E29: 32 | H29: 52 | K29: 72 | L29: Klik untuk pilih | N29: 88 | T29: AN | U29: =I93 -> 0 | V29: =IF($D$8<=20,AU47,AV47) -> 77 | W29: =IF(V29<=80,"Sangat Rendah",IF(V29<=94,"Rendah",IF(V29<=99,"Sedang",IF(V29<=104,"Cukup",IF(V29<=118,"Tinggi","Sangat Tinggi"))))) -> Sangat Rendah | AA29: 23 | AE29: 136 | AK29: 23 | AO29: 133 | AU29: 23 | AY29: 122 | BE29: 23 | BI29: 115 | BO29: 23 | BS29: 115 | BY29: 23 | CC29: =AVERAGE(CC28,CC30) -> 113 | CI29: 23 | CM29: 111 | CS29: 23 | CW29: 110 | DC29: 23 | DG29: 110 | DM29: 23 | DQ29: 109 | DW29: 23 | EA29: 110 | EG29: 23 | EK29: 111 | EQ29: 23 | EU29: 110
B30: 13 | E30: 33 | H30: 53 | K30: 73 | L30: Klik untuk pilih | N30: 89 | T30: GE | U30: =K89 -> 0 | V30: =IF($D$8<=20,AU48,AV48) -> 73 | W30: =IF(V30<=80,"Sangat Rendah",IF(V30<=94,"Rendah",IF(V30<=99,"Sedang",IF(V30<=104,"Cukup",IF(V30<=118,"Tinggi","Sangat Tinggi"))))) -> Sangat Rendah | X30: =V30+V32 -> 145 | AA30: 24 | AE30: 138 | AK30: 24 | AO30: 135 | AU30: 24 | AY30: 123 | BE30: 24 | BI30: 117 | BO30: 24 | BS30: 116 | BY30: 24 | CC30: 115 | CI30: 24 | CM30: 112 | CS30: 24 | CW30: 111 | DC30: 24 | DG30: 112 | DM30: 24 | DQ30: 110 | DW30: 24 | EA30: 111 | EG30: 24 | EK30: 112 | EQ30: 24 | EU30: 111
B31: 14 | E31: 34 | H31: 54 | K31: 74 | L31: Klik untuk pilih | N31: 90 | T31: ME | U31: =L119 -> 0 | V31: =IF($D$8<=20,AU49,AV49) -> 77 | W31: =IF(V31<=80,"Sangat Rendah",IF(V31<=94,"Rendah",IF(V31<=99,"Sedang",IF(V31<=104,"Cukup",IF(V31<=118,"Tinggi","Sangat Tinggi"))))) -> Sangat Rendah | X31: =V29+V33 -> 154 | AA31: 25 | AE31: 141 | AK31: 25 | AO31: 138 | AU31: 25 | AY31: 125 | BE31: 25 | BI31: 119 | BO31: 25 | BS31: 118 | BY31: 25 | CC31: =AVERAGE(CC30,CC32) -> 116.5 | CI31: 25 | CM31: 114 | CS31: 25 | CW31: 113 | DC31: 25 | DG31: 114 | DM31: 25 | DQ31: 112 | DW31: 25 | EA31: 113 | EG31: 25 | EK31: 114 | EQ31: 25 | EU31: 113
B32: 15 | E32: 35 | H32: 55 | K32: 75 | L32: Klik untuk pilih | N32: 91 | T32: RA | U32: =O93 -> 0 | V32: =IF($D$8<=20,AU50,AV50) -> 72 | W32: =IF(V32<=80,"Sangat Rendah",IF(V32<=94,"Rendah",IF(V32<=99,"Sedang",IF(V32<=104,"Cukup",IF(V32<=118,"Tinggi","Sangat Tinggi"))))) -> Sangat Rendah | X32: =IF(X30>X31,X30-X31,X31-X30) -> 9 | AA32: 26 | AE32: 144 | AK32: 26 | AO32: 140 | AU32: 26 | AY32: 127 | BE32: 26 | BI32: 121 | BO32: 26 | BS32: 119 | BY32: 26 | CC32: 118 | CI32: 26 | CM32: 116 | CS32: 26 | CW32: 114 | DC32: 26 | DG32: 115 | DM32: 26 | DQ32: 113 | DW32: 26 | EA32: 114 | EG32: 26 | EK32: 115 | EQ32: 26 | EU32: 115
B33: 16 | E33: 36 | H33: 56 | K33: 76 | L33: Klik untuk pilih | N33: 92 | T33: ZR | U33: =C119 -> 0 | V33: =IF($D$8<=20,AU51,AV51) -> 77 | W33: =IF(V33<=80,"Sangat Rendah",IF(V33<=94,"Rendah",IF(V33<=99,"Sedang",IF(V33<=104,"Cukup",IF(V33<=118,"Tinggi","Sangat Tinggi"))))) -> Sangat Rendah | AA33: 27 | AE33: 147 | AK33: 27 | AO33: 143 | AU33: 27 | AY33: 129 | BE33: 27 | BI33: 123 | BO33: 27 | BS33: 121 | BY33: 27 | CC33: =AVERAGE(CC32,CC34) -> 119.5 | CI33: 27 | CM33: 118 | CS33: 27 | CW33: 116 | DC33: 27 | DG33: 117 | DM33: 27 | DQ33: 115 | DW33: 27 | EA33: 116 | EG33: 27 | EK33: 117 | EQ33: 27 | EU33: 117
B34: 17 | E34: 37 | H34: 57 | N34: 93 | T34: FA | U34: =F119 -> 0 | V34: =IF($D$8<=20,AU52,AV52) -> 74 | W34: =IF(V34<=80,"Sangat Rendah",IF(V34<=94,"Rendah",IF(V34<=99,"Sedang",IF(V34<=104,"Cukup",IF(V34<=118,"Tinggi","Sangat Tinggi"))))) -> Sangat Rendah | AA34: 28 | AE34: 149 | AK34: 28 | AO34: 146 | AU34: 28 | AY34: 130 | BE34: 28 | BI34: 124 | BO34: 28 | BS34: 122 | BY34: 28 | CC34: 121 | CI34: 28 | CM34: 119 | CS34: 28 | CW34: 117 | DC34: 28 | DG34: 118 | DM34: 28 | DQ34: 116 | DW34: 28 | EA34: 117 | EG34: 28 | EK34: 118 | EQ34: 28 | EU34: 118
B35: 18 | E35: 38 | H35: 58 | N35: 94 | T35: WU | U35: =I119 -> 0 | V35: =IF($D$8<=20,AU53,AV53) -> 74 | W35: =IF(V35<=80,"Sangat Rendah",IF(V35<=94,"Rendah",IF(V35<=99,"Sedang",IF(V35<=104,"Cukup",IF(V35<=118,"Tinggi","Sangat Tinggi"))))) -> Sangat Rendah | AA35: 29 | AE35: 152 | AK35: 29 | AO35: 148 | AU35: 29 | AY35: 132 | BE35: 29 | BI35: 126 | BO35: 29 | BS35: 124 | BY35: 29 | CC35: =AVERAGE(CC34,CC36) -> 123 | CI35: 29 | CM35: 121 | CS35: 29 | CW35: 119 | DC35: 29 | DG35: 120 | DM35: 29 | DQ35: 118 | DW35: 29 | EA35: 119 | EG35: 29 | EK35: 120 | EQ35: 29 | EU35: 120
B36: 19 | E36: 39 | H36: 59 | N36: 95 | T36: JML | U36: =SUM(U27:U35) -> 0 | V36: =AU54 -> 0 | AA36: 30 | AE36: 154 | AK36: 30 | AO36: 149 | AU36: 30 | AY36: 134 | BE36: 30 | BI36: 127 | BO36: 30 | BS36: 125 | BY36: 30 | CC36: 125 | CI36: 30 | CM36: 122 | CS36: 30 | CW36: 120 | DC36: 30 | DG36: 122 | DM36: 30 | DQ36: 120 | DW36: 30 | EA36: 120 | EG36: 30 | EK36: 121 | EQ36: 30 | EU36: 121
B37: 20 | E37: 40 | H37: 60 | N37: 96 | T37: IQ | U37: =VLOOKUP(V36,AB46:AP226,15) -> 0 | W37: =IF(U37<=65,"Mentally Defective",IF(U37<=79,"Borderline Defective",IF(U37<=90,"Low Average",IF(U37<=110,"Average",IF(U37<=119,"High Average",IF(U37<=127,"Superior",IF(U37<=139,"Very Superior","Genius"))))))) -> Mentally Defective | AA37: 31 | AE37: 157 | AK37: 31 | AO37: 152 | AU37: 31 | AY37: 136 | BE37: 31 | BI37: 129 | BO37: 31 | BS37: 127 | BY37: 31 | CC37: =AVERAGE(CC36,CC38) -> 126.5 | CI37: 31 | CM37: 124 | CS37: 31 | CW37: 122 | DC37: 31 | DG37: 124 | DM37: 31 | DQ37: 121 | DW37: 31 | EA37: 122 | EG37: 31 | EK37: 123 | EQ37: 31 | EU37: 123
T38: Dominasi | W38: =IF(X32<=10,"Seimbang",IF(X30>X31,"Eksak",IF(X30<X31,"Non Eksak"))) -> Seimbang | AA38: 32 | AE38: 159 | AK38: 32 | AO38: 154 | AU38: 32 | AY38: 137 | BE38: 32 | BI38: 130 | BO38: 32 | BS38: 129 | BY38: 32 | CC38: 128 | CI38: 32 | CM38: 126 | CS38: 32 | CW38: 123 | DC38: 32 | DG38: 125 | DM38: 32 | DQ38: 122 | DW38: 32 | EA38: 124 | EG38: 32 | EK38: 124 | EQ38: 32 | EU38: 125
B41: ZR | E41: FA | H41: WU | K41: ME
B42: No | C42: Jawaban Subjek | E42: No | F42: Jawaban Subjek | H42: No | I42: Jawaban Subjek | K42: No | L42: Jawaban Subjek
...

Sheet Bantuan
A1: BANTUAN INTERPRETASI | G1: PERHATIAN
A3: NO | B3: =IST!D4 -> 1 | C3: Sangat Tinggi | D3: Sangat Bagus | E3: Keterangan | G3: Bagian bantuan ini hanya berfungsi memberikan bantuan pemahaman terhadap hasil tes dan tidak bisa dijadikan referensi pengambilan keputusan, anda tetap harus mengacu kepada hasil tes pada worksheet "IST"
A4: NAMA | B4: =IST!D5 -> Arman | C4: Tinggi | D4: Bagus
A5: USIA | B5: =IST!D8 -> 26 | C5: Sedang | D5: Rata Rata
A6: TGL TES | B6: =IST!D7 -> 43754 | C6: Rendah | D6: Kesulitan melakukan
C7: Sangat Rendah | D7: Tidak bisa semua
A8: SUBTES | B8: ASPEK YG DI UKUR | C8: ASPEK TERUKUR | D8: HASIL TES
A9: SE (Satzerganzng) | B9: Pembentukan keputusan, common sense (memanfaatkan pengalaman masa lalu), pebekanan pada praktis-konkrit,pemaknaan realitas dan berpikir secara mandiri | C9: Berpikir Konkrit Praktis, Berpikir Logis, Akal Sehat(Common Sense), Pembentukan Keputusan, Pemaknaan Realita, Berpikir mandiri | D9: =IST!W27 -> Sangat Rendah
A10: WA (Wortausuahl) | B10: Kemampuan bahasa,perasaan empati, berpikir induktif menggunakan bahasa dan memahami pengertian bahasa | C10: Rasa bahasa, berpikir verbal, pengertian bahasa, kemampuan empati (menghayati), komponen reseptif | D10: =IST!W28 -> Sangat Rendah
A11: AN (Analogien) | B11: Kemampuan fleksibilitas dalam berpikir, daya mengkombinasikan, mendeteksi dan memindahkan hubungan-hubungan,serta kejelasan dan kenkonsekuenan dalam berpikir | C11: Daya mengkombinasikan, fleksibilitas/kelincahan berpikir, Mentransfer hubungan, Kejelasan dan konsekuen dalam berpikir, Analisa yang bersifat dugaan, Suatu perkiraan yang paling berarti dalam pengembangan studi ilmiah | D11: =IST!W29 -> Sangat Rendah
A12: GE (Gmeisamkeiten) | B12: Abstraksi verbal, kemampuan untuk menyatakan pengertian akan sesuatu dalam bentuk bahasa, membentuk suatu pengertian atau mencari inti persoalan serta berpikir logis dalam suatu bahasa | C12: Daya atraksi verbal, Pembentukan konsep (Pengertian), Berpikir logis dalam bentuk bahasa | D12: =IST!W30 -> Sangat Rendah
A13: RA (Rechen Aufgaben) | B13: Kemampuan berpikir praktis dalam berhitung, berpikir induktif, reasoning dan kemampuan mengambil kesimpulan | C13: Berpikir praktis dalam masalah hitungan, berpikir logis objektif, berpikir matematis, mengambil keputusan | D13: =IST!W31 -> Sangat Rendah
A14: ZR (Zahlen Reihen) | B14: Berpikir teoritis dengan hitungan,berpikir induktif dengan angka-angka,serta kelincahan dalam berpikir | C14: Berpikir teoritis dalam berhitung, berpikir induktif angka, kelincahan berpikir, mengenali komponen ritmis | D14: =IST!W32 -> Sangat Rendah
A15: FA (Form Ausuahl) | B15: membayangngkan,kemampuan mengkonstruksi (sintesa dan analisa), berpikir konkrit menyeluruh serta memasukan bagian pada keseluruhan | C15: Kemampuan membayangkan, Kemampuan mengamati, berpikir secara utuh menyeluruh, mengenali komponen konstruktif | D15: =IST!W33 -> Sangat Rendah
A16: WU (Wurfal Aufgaben) | B16: Daya bayang ruang, kemampuan tiga dimensi, analitis serta kemampuan konstruktif teknis | C16: Daya bayang ruang, Mengenali konstruksi teknis, berpikir analitis | D16: =IST!W34 -> Sangat Rendah
A17: ME (Merk Aufgaben) | B17: Daya ingat, konsentrasi yang menetap dan daya tahan | C17: Atensi, Memori mengingat kata yang telah dipelajari | D17: =IST!W35 -> Sangat Rendah
A18: PROFIL POLA PIKIR
A20: Corak Berpikir | B20: Festigung Flexibitat merupakan dua kutub pemikiran yang ekstrim. Kutub Festigung artinya mengarah ke berpikir Exact, sementara Flexibitat mengarah ke ke berpikir non-exact. Akan lebih condong ke salah satu seiring dengan bertambahnya usia | C20: Festigung (Pola Pemikiran exact) | D20: =IF(IST!A130>IST!C130,"YES",NO) -> #NAME?
C21: Flexibitat (Pola Pemikiran non-exact) | D21: =IF(IST!A130>IST!C130,"NO",YES) -> #NAME?
A22: Cara Berpikir | B22: Untuk menentukan cara berpikir silahkan lihat grafik hasil tes untuk 4 subtes pertama (SE,WA,AN,GE) jika grafik berbentuk M maka peserta tes memiliki cara berpikir "M", jika berbentuk W maka cara berpikir W, lihat keterangan pada tabel disamping. Jika bentuknya kurang jelas maka tidak bisa ditentukan | C22: M (Verbal-Teoritis) | D22: Lihat grafik dan tuliskan YES disini jika M
C23: W (Praktis-Konkrit) | D23: Lihat grafik dan tuliskan YES disini jika W

Sheet Kunci Soal 1-3,7-9
B1: SUBTES
B2: NO. | C2: I | D2: NO. | E2: II | F2: NO. | G2: III | H2: NO. | I2: V | J2: NO. | K2: VI | L2: NO. | M2: VII | N2: NO. | O2: VIII | P2: NO. | Q2: IX
B3: 1 | C3: E | D3: 21 | E3: B | F3: 41 | G3: C | H3: 77 | I3: 35 | J3: 97 | K3: 27 | L3: 117 | M3: A | N3: 137 | O3: A | P3: 157 | Q3: D
B4: 2 | C4: C | D4: 22 | E4: B | F4: 42 | G4: E | H4: 78 | I4: 280 | J4: 98 | K4: 25 | L4: 118 | M4: C | N4: 138 | O4: C | P4: 158 | Q4: E
B5: 3 | C5: D | D5: 23 | E5: D | F5: 43 | G5: D | H5: 79 | I5: 205 | J5: 99 | K5: 27 | L5: 119 | M5: B | N5: 139 | O5: D | P5: 159 | Q5: B
B6: 4 | C6: D | D6: 24 | E6: C | F6: 44 | G6: D | H6: 80 | I6: 26 | J6: 100 | K6: 15 | L6: 120 | M6: A | N6: 140 | O6: E | P6: 160 | Q6: A
B7: 5 | C7: D | D7: 25 | E7: C | F7: 45 | G7: D | H7: 81 | I7: 30 | J7: 101 | K7: 46 | L7: 121 | M7: D | N7: 141 | O7: A | P7: 161 | Q7: C
B8: 6 | C8: B | D8: 26 | E8: C | F8: 46 | G8: A | H8: 82 | I8: 70 | J8: 102 | K8: 10 | L8: 122 | M8: B | N8: 142 | O8: C | P8: 162 | Q8: A
B9: 7 | C9: C | D9: 27 | E9: C | F9: 47 | G9: D | H9: 83 | I9: 45 | J9: 103 | K9: 42 | L9: 123 | M9: C | N9: 143 | O9: D | P9: 163 | Q9: D
B10: 8 | C10: A | D10: 28 | E10: D | F10: 48 | G10: B | H10: 84 | I10: 50 | J10: 104 | K10: 7 | L10: 124 | M10: E | N10: 144 | O10: C | P10: 164 | Q10: E
B11: 9 | C11: E | D11: 29 | E11: D | F11: 49 | G11: E | H11: 85 | I11: 84 | J11: 105 | K11: 5 | L11: 125 | M11: E | N11: 145 | O11: E | P11: 165 | Q11: C
B12: 10 | C12: B | D12: 30 | E12: A | F12: 50 | G12: D | H12: 86 | I12: 78 | J12: 106 | K12: 14 | L12: 126 | M12: D | N12: 146 | O12: A | P12: 166 | Q12: B
B13: 11 | C13: C | D13: 31 | E13: E | F13: 51 | G13: C | H13: 87 | I13: 19 | J13: 107 | K13: 8 | L13: 127 | M13: E | N13: 147 | O13: B | P13: 167 | Q13: B
B14: 12 | C14: D | D14: 32 | E14: A | F14: 52 | G14: C | H14: 88 | I14: 6 | J14: 108 | K14: 14 | L14: 128 | M14: B | N14: 148 | O14: D | P14: 168 | Q14: A
... B22: 20 | C22: B | D22: 40 | E22: C | F22: 60 | G22: E | H22: 96 | I22: 1 | J22: 116 | K22: 10 | L22: 136 | M22: A | N22: 156 | O22: C | P22: 176 | Q22: D

Sheet KUNCI IST (2)
A1: LEMBAR JAWABAN I.S.T.
A3: Nomor | D3: : | L3: L / P
A4: Nama | D4: :
A5: Tempat Tanggal Lahir | D5: : | K5: Usia: | M5: Thn
A6: Pendidikan Terakhir | D6: :
A7: Tujuan Pemeriksaan | D7: :
A8: Tanggal Pemeriksaan | D8: :
A10: SUBTES 1 | D10: SUBTES 2 | G10: SUBTES 3 | J10: SUBTES 4
A11: No. | B11: Jawaban | D11: No. | E11: Jawaban | G11: No. | H11: Jawaban | J11: No. | K11: Jawaban
A12: 1 | B12: E | D12: 21 | E12: A | G12: 41 | H12: C | J12: 61
A13: 2 | B13: C | D13: 22 | E13: A | G13: 42 | H13: E | J13: 62
A14: 3 | B14: D | D14: 23 | E14: D | G14: 43 | H14: D | J14: 63
A15: 4 | B15: D | D15: 24 | E15: C | G15: 44 | H15: D | J15: 64
A16: 5 | B16: D | D16: 25 | E16: C | G16: 45 | H16: D | J16: 65
A17: 6 | B17: D | D17: 26 | E17: C | G17: 46 | H17: B | J17: 66
A18: 7 | B18: C | D18: 27 | E18: C | G18: 47 | H18: D | J18: 67
A19: 8 | B19: A | D19: 28 | E19: D | G19: 48 | H19: A | J19: 68
A20: 9 | B20: E | D20: 29 | E20: D | G20: 49 | H20: E | J20: 69
A21: 10 | B21: B | D21: 30 | E21: A | G21: 50 | H21: D | J21: 70
A22: 11 | B22: C | D22: 31 | E22: C | G22: 51 | H22: C | J22: 71
A23: 12 | B23: D | D23: 32 | E23: A | G23: 52 | H23: C | J23: 72
... A27: 16 | B27: A | D27: 36 | E27: A | G27: 56 | H27: C | J27: 76
A28: 17 | B28: B | D28: 37 | E28: D | G28: 57 | H28: C
A29: 18 | B29: E | D29: 38 | E29: E | G29: 58 | H29: D | J29: RW
A30: 19 | B30: C | D30: 39 | E30: B | G30: 59 | H30: E
A31: 20 | B31: B | D31: 40 | E31: C | G31: 60 | H31: E
A33: RW | D33: RW | G33: RW
A36: SUBTES 5 | D36: SUBTES 6 | G36: SUBTES 7 | J36: SUBTES 8 | M36: SUBTES 9
A37: No. | B37: Jawaban | D37: No. | E37: Jawaban | G37: No. | H37: Jawaban | J37: No. | K37: Jawaban | M37: No. | N37: Jawaban
A38: 77 | D38: 97 | G38: 117 | J38: 137 | M38: 157
A39: 78 | D39: 98 | G39: 118 | J39: 138 | M39: 158
A40: 79 | D40: 99 | G40: 119 | J40: 139 | M40: 159
A41: 80 | D41: 100 | G41: 120 | J41: 140 | M41: 160
A42: 81 | D42: 101 | G42: 121 | J42: 141 | M42: 161
A43: 82 | D43: 102 | G43: 122 | J43: 142 | M43: 162
A44: 83 | D44: 103 | G44: 123 | J44: 143 | M44: 163
A45: 84 | D45: 104 | G45: 124 | J45: 144 | M45: 164
A46: 85 | D46: 105 | G46: 125 | J46: 145 | M46: 165
A47: 86 | D47: 106 | G47: 126 | J47: 146 | M47: 166
A48: 87 | D48: 107 | G48: 127 | J48: 147 | M48: 167
...

Sheet Kunci Soal 4
A2: KUNCI JAWABAN KELOMPOK SOAL 4
A3: NO. | B3: SOAL | C3: SKOR 2 | D3: SKOR 1 | E3: SKOR 0
A4: 61. | B4: Mawar - Melati | C4: - Bunga - Kembang | D4: - Tumbuh-tumbuhan | E4: - Pohon
C5: - Perdu | D5: - Tangkai - Harum
A7: 62. | B7: Mata - Telinga | C7: - Alat indera - Indera | D7: - Organ | E7: - Kepala
C8: - Panca Indera | D8: - Alat tubuh
A10: 63. | B10: Gula - Intan | C10: - Hablur - Kristal | D10: - Berkilauan
C11: - Zat arang | D11: - Mengkilat - Bening
A13: 64. | B13: Salju - Hujan | C13: - Musim | D13: - Cuaca | E13: - Iklim
A15: 65. | B15: Pengantar Surat - | C15: - Pembawa Berita | D15: - Telekomunikasi
B16: Telepon | C16: - Alat Perhubungan | D16: - Perhubungan
D17: - Komunikasi
A19: 66. | B19: Kamera - Kacamata | C19: - alat optik | D19: - Lensa | E19: - Melihat - alat
C20: - Optik | E20: - Alat Melihat
A22: 67. | B22: Lambung - Usus | C22: - Alat Pencernaan | D22: - Jalan Makanan | E22: - Makanan
D23: - Perut - Isi Perut
D24: - Pencernaan Makanan
A26: 68. | B26: Banyak - Sedikit | C26: - Jumlah/Kuantitas | D26: - Mengukur | E26: - Uang
C27: - Penyebut Jumlah | D27: - Ukuran
C28: - Penyertaan Jumlah
A30: 69. | B30: Telur - Benih | C30: - Bibit/bakal/embrio | D30: - Sel | E30: - Pertanian
C31: - Alat Pembiak | D31: - Pembiakan | E31: - Keturunan
C32: - Permulaan Penghidupan
A34: 70. | B34: Bendera - Lencana | C34: - Simbol | D34: - Nama | E34: - Warna
C35: - Lambang - Tanda | D35: - Tanda Pengenal
A37: 71. | B37: Rumput - Gajah | C37: - Makhluk - Organism | D37: - Tumbuh - Ilmu hayat | E37: - Hidup - Hutan
C38: - Makhluk Hidup | D38: - Biologi | E38: - Hayat
A40: 72. | B40: Ember - Kontong | C40: - Wadah - Tempat pengisi | D40: - Alat - Tempat sesuatu | E40: - Lubang
C41: - Tempat Penyimpan | D41: - Tempat - Benda
A43: 73. | B43: Awal - Akhir | C43: - Pengertian Waktu | D43: - Waktu - Lamanya | E43: - Kata Waktu
C44: - Batas | D44: - Masa/saat | E44: - Buku
A46: 74. | B46: Kikir - Boros | C46: - Kata Sifat - Watak | D46: - Sifat | E46: - Uang - Karakter
C47: - Sifat Karakter | E47: - Watak
A49: 75. | B49: Penawaran - | C49: - Regulator harga | D49: - Dagang - Pembelian | E49: - Lawan kata
B50: Permintaan | C50: - Pengertian Ekonomi | D50: - Penjualan
D51: - Niaga - Jual beli
A53: 76. | B53: Atas - Bawah | C53: - Pengertian ruang | D53: - Arah - Tempat/ruang | E53: - Daerah - Ruangan
C54: - Penyebut ruang | D54: - Letak - penunjuk tempat | E54: - Tingkatan - Kata
D55: - Penentuan Daerah
